Workbook

Sheet July-25
A1: Date | B1: SO | C1: Opening Balance | D1: Received Cash | E1: Expenses | F1: Item Details | G1: Balance Amount
A2: 45813 | B2: ALL | C2: 0 | D2: 9310 | E2: 0 | F2: NIL | G2: =C2+D2-E2 -> 9310
A3: 45814 | B3: TARAK | C3: =G2 -> 9310 | D3: 0 | E3: 0 | F3: NIL | G3: =C3+D3-E3 -> 9310
A4: 45815 | B4: SAI | C4: =G3 -> 9310 | D4: 17060 | E4: 0 | F4: NIL | G4: =C4+D4-E4 -> 26370
A5: 45816 | B5: NIL | C5: =G4 -> 26370 | D5: 0 | E5: 0 | F5: NIL | G5: =C5+D5-E5 -> 26370
A6: 45817 | B6: NIL | C6: =G5 -> 26370 | D6: 0 | E6: 4000 | F6: TULASI EXPENSES | G6: =C6+D6-E6 -> 22370
A7: 45818 | B7: TARAK | C7: =G6 -> 22370 | D7: 0 | E7: 0 | F7: NIL | G7: =C7+D7-E7 -> 22370
A8: 45819 | B8: SAI | C8: =G7 -> 22370 | D8: 4290 | E8: 3000 | F8: SANTOSH DIESEL | G8: =C8+D8-E8 -> 23660
A9: 45820 | B9: TARAK | C9: =G8 -> 23660 | D9: 22430 | E9: 110 | F9: FEVIQUIC,CELLO TAPE-110 | G9: =C9+D9-E9 -> 45980
A10: 45821 | B10: TARAK | C10: =G9 -> 45980 | D10: 0 | E10: 8200 | F10: RO FILTERS-5840,PETROL-260,STAFF DINNER-2100 | G10: =C10+D10-E10 -> 37780
A11: 45822 | B11: SAI | C11: =G10 -> 37780 | D11: 10060 | E11: 3000 | F11: VIZIANAGARAM VEHICLE | G11: =C11+D11-E11 -> 44840
A12: 45823 | B12: SUNDAY | C12: =G11 -> 44840 | D12: 0 | E12: 0 | F12: NIL | G12: =C12+D12-E12 -> 44840
A13: 45824 | B13: SAI | C13: =G12 -> 44840 | D13: 26680 | E13: 6500 | F13: DIESEL FOR 2 VEHICLES-6K,FAST TAG FOR SANTOSH VEHICLE-500 | G13: =C13+D13-E13 -> 65020
A14: 45825 | B14: SAI | C14: =G13 -> 65020 | D14: 9370 | E14: 8600 | F14: MILK BILL MAY MONTH-8400,NAVEEN PETROL-200 | G14: =C14+D14-E14 -> 65790
... A19: 45829 | B19: SAI | C19: =G18 -> 28070 | D19: 0 | E19: 2000 | F19: TATA ACE KANCHARAPALEM ANNA CANTEEN-2000 | G19: =C19+D19-E19 -> 26070
A20: 45830 | C20: =G19 -> 26070 | G20: =C20+D20-E20 -> 26070
A21: 45831 | B21: SAI | C21: =G20 -> 26070 | D21: 11650 | E21: 3000 | F21: DIESEL(SANTOSH VECHILE) | G21: =C21+D21-E21 -> 34720
A22: 45832 | B22: SAI | C22: =G21 -> 34720 | D22: 13710 | E22: 3000 | F22: DIESEL(RAMESH VECHILE) | G22: =C22+D22-E22 -> 45430
A23: 45833 | B23: SAI | C23: =G22 -> 45430 | D23: 7670 | E23: 0 | F23: NIL | G23: =C23+D23-E23 -> 53100
A24: 45834 | B24: SAI | C24: =G23 -> 53100 | D24: 7010 | E24: 9370 | F24: SANTOSH DIESEL-3000,GEOLOGIEST FEE-5000,CLUSTER BOND PAPER 10'N0-1200,COCONUT-170 | G24: =C24+D24-E24 -> 50740
A25: 45835 | B25: SAI | C25: =G24 -> 50740 | D25: 5920 | E25: 1000 | F25: DIESEL(RAMESH VECHILE) | G25: =C25+D25-E25 -> 55660
A26: 45836 | B26: SAI | C26: =G25 -> 55660 | D26: 9980 | E26: 51500 | F26: SUDHAKAR-49,500,RAMESH DIESEL-2000 | G26: =C26+D26-E26 -> 14140
A27: 45838 | B27: SAI | C27: =G26 -> 14140 | D27: 8570 | E27: 3450 | F27: SANTOSH DIESEL-3000,ASSIL-100,NUM PLATE-350 | G27: =C27+D27-E27 -> 19260
A28: 45839 | B28: SAI | C28: =G27 -> 19260 | D28: 5440 | E28: 9850 | F28: SV LABS-8850,RAPIDO GWK-700,FIRST AID KALASHI-300 | G28: =C28+D28-E28 -> 14850
A29: 45840 | B29: SAI | C29: =G28 -> 14850 | D29: 7780 | E29: 5820 | F29: EAICHER DIESEL-3000,EAICHER TOLLGATE-1120,DRIVER BETA-200,KALASHI DINNER-600(4 MEMBERS),RAMESH DIESEL-900. | G29: =C29+D29-E29 -> 16810
A30: 45841 | B30: SAI | C30: =G29 -> 16810 | D30: 8720 | E30: 9580 | F30: RAMESH DIESEL-3000,EXTRA HAMALI-4080,ARILOVA UNLOADING-500,ROPE-1700,NO ENTRY FEE-300 | G30: =C30+D30-E30 -> 15950
A31: 45842 | B31: SAI | C31: =G30 -> 15950 | D31: 8380 | E31: 290 | F31: SHANKAR SHOP PETROL-150,MILK-140 | G31: =C31+D31-E31 -> 24040
A32: 45843 | B32: NIL | C32: =G31 -> 24040 | D32: 0 | E32: 3670 | F32: SANTOSH DIESEL-3000,SANTOGH TOLL GATE-500,STATIONARY-170 | G32: =C32+D32-E32 -> 20370
... A34: 45846 | B34: SAI | C34: =G33 -> 27060 | D34: 11280 | E34: 15287 | F34: BELT-1300,BELT-4,177,MEALS FOR KALASHI-260,RAMESH DIESERL-3000,RAPIDO,350,MILK-200,BAGYA BIS-1000,KALASHI(4)-5000 | G34: =C34+D34-E34 -> 23053
A35: 45847 | C35: =G34 -> 23053 | D35: 0 | E35: 13300 | F35: BANDI RAJU-6000,KALASHI DINNER-1000,SANTOSH DIESEL-3000,PANKAJ PETROL-500,EXTRA KALASHI-2,800 | G35: =C35+D35-E35 -> 9753
A36: 45848 | B36: NIL | C36: =G35 -> 9753 | D36: 0 | E36: 0 | F36: NIL | G36: =C36+D36-E36 -> 9753
A37: 45849 | C37: =G36 -> 9753 | D37: 7500 | E37: 5850 | F37: RAMESH DIESEL-3000,SANTOSH DIESEL-2000,ENGINE OIL-400,PETBLOWING SPARES-450 | G37: =C37+D37-E37 -> 11403
A38: 45850 | B38: SAI | C38: =G37 -> 11403 | D38: 10700 | E38: 2000 | F38: RAJU BOLERO-2000 | G38: =C38+D38-E38 -> 20103
A39: 45851 | B39: SUNDAY | C39: =G38 -> 20103 | D39: 0 | E39: 0 | F39: NIL | G39: =C39+D39-E39 -> 20103
A40: 45852 | B40: SANTOSH | C40: =G39 -> 20103 | D40: 14750 | E40: 1600 | F40: SANTOSH DIESEL-1000,KALASHI LUNCH AT SIMHACHALAM-600 | G40: =C40+D40-E40 -> 33253
A41: 45853 | B41: RAMESH | C41: =G40 -> 33253 | D41: 11240 | E41: 3000 | F41: SANTOSH DIESEL-3000 | G41: =C41+D41-E41 -> 41493
A42: 45854 | B42: RAMESH | C42: =G41 -> 41493 | D42: 11900 | E42: 36650 | F42: RAMESH DIESEL-3000,EICHER DIESEL-6000,FAST TAG REGISTRATION-1300,FAST TAG RECHARGE-1000,BETA-200,MILK-150,VINODH-25,000/- | G42: =C42+D42-E42 -> 16743
A43: 45855 | B43: RAMESH | C43: =G42 -> 16743 | D43: 10320 | E43: 9430 | F43: SANTOSH DIESEL-3000,VINOD-5000,MILK-180,RAJAM KALASHI DINNER-800,EICHER GRRZING-350,FAST TAG STICKER-100 | G43: =C43+D43-E43 -> 17633
A44: 45856 | B44: NIL | C44: =G43 -> 17633 | D44: 0 | E44: 3000 | F44: SANTOSH DIESEL-3000 | G44: =C44+D44-E44 -> 14633
A45: 45857 | B45: RAMESH | C45: =G44 -> 14633 | D45: 5900 | E45: 7732 | F45: FRIDGE STICKRING-1000,STAFF GROCERY-5,420,ELECTRYCITY BILL 3BHK-1312 | G45: =C45+D45-E45 -> 12801
...

Sheet Aug-25
A1: Date | B1: SO | C1: Opening Balance | D1: Received Cash | E1: Expenses | F1: Item Details | G1: Balance Amount
A2: 45870 | B2: KIRAN | C2: ='July-25'!G57 -> 8441 | D2: 5490 | E2: 0 | F2: NIL | G2: =C2+D2-E2 -> 13931
A3: 45871 | B3: RAMESH | C3: =G2 -> 13931 | D3: 8380 | E3: 7700 | F3: RAMESH DIESEL-3000,SANTOSH DIESEL-3000,BALL WALL-1500,TEFFLON TAPE-200 | G3: =C3+D3-E3 -> 14611
A4: 45872 | B4: SUNDAY | C4: =G3 -> 14611 | G4: =C4+D4-E4 -> 14611
A5: 45873 | B5: RAMESH | C5: =G4 -> 14611 | D5: 12010 | E5: 160 | F5: 16'AMPS PLUG-100,SCREWS-60/- | G5: =C5+D5-E5 -> 26461
A6: 45874 | B6: RAMESH | C6: =G5 -> 26461 | D6: 12690 | E6: 7440 | F6: ROAD TAX-6340,100.RS BOND PAPER-600,STAFF VEGETABLES-500 | G6: =C6+D6-E6 -> 31711
A7: 45875 | B7: KIRAN | C7: =G6 -> 31711 | D7: 5280 | E7: 15200 | F7: RAMESH DIESEL-3000,SANTOSH DIESEL-3000,FAST TAG RECHARGE-500,EICHER DIESEL-6000,DRIVER BETA-200,PRINTER INK-400,KALASHI LUNCH-700,ENGINE OIL-1400 | G7: =C7+D7-E7 -> 21791
A8: 45876 | B8: RAMESH | C8: =G7 -> 21791 | D8: 23300 | E8: 0 | F8: NIL | G8: =C8+D8-E8 -> 45091
A9: 45877 | B9: NIL | C9: =G8 -> 45091 | D9: 0 | E9: 11490 | F9: EAICHER DIESEL-6000,BETA-200,POLICE-100,KALASHI LUNCH-700,STAFF SNACKS-300,STAFF DINNER-1040,RAMESH DIESEL-3000,DRIVER DINNER-150 | G9: =C9+D9-E9 -> 33601
A10: 45878 | B10: RAMESH | C10: =G9 -> 33601 | D10: 9640 | E10: 8850 | F10: RAMESH DIESEL-3000,HEATING BLOWER-2800,PETROL-200,EXTRA KALASHI-2700(3),BIRLA WHITE-150 | G10: =C10+D10-E10 -> 34391
A11: 45879 | B11: SUNDAY | C11: =G10 -> 34391 | D11: 0 | E11: 0 | F11: NIL | G11: =C11+D11-E11 -> 34391
A12: 45880 | B12: RAMESH | C12: =G11 -> 34391 | D12: 13490 | E12: 5390 | F12: WATER PIPE&NIPPEL-390,EAICHER DIESEL-5000, | G12: =C12+D12-E12 -> 42491
A13: 45881 | B13: RAMESH | C13: =G12 -> 42491 | D13: 3100 | E13: 12660 | F13: SANTOSH DIESEL-3000,A4 SHEET BUNDLE-260,RAMESH DIESEL-2000,HAMALI LUNCH-400,3BHK RENT-7000 | G13: =C13+D13-E13 -> 32931
A14: 45882 | B14: RAMESH | C14: =G13 -> 32931 | D14: 9250 | E14: 6310 | F14: STAFF GROSARIES-5500,STAFF CURRY-200,OZONATTION SSR-410,PETROL-200 | G14: =C14+D14-E14 -> 35871
A15: 45883 | B15: RAMESH | C15: =G14 -> 35871 | D15: 3710 | E15: 5970 | F15: SANTOSH DIESEL-2000PP RAMESH DIESEL-3000,ALL TYPE OF BOLTS-3570,TAGS-100,MANAGER LUNCH-300, | G15: =C15+D15-E15 -> 33611 | H15: 3000 EXTRA
A16: 45884 | B16: HOLIDAY | C16: =G15 -> 33611 | D16: 0 | E16: 0 | F16: HOLIDAY | G16: =C16+D16-E16 -> 33611
A17: 45885 | B17: RAMESH | C17: =G16 -> 33611 | D17: 6900 | E17: 4000 | F17: SANTOSH DIESEL-3000,HAMALI LUNCH-1000 | G17: =C17+D17-E17 -> 36511
A18: 45886 | B18: SUNDAY | C18: =G17 -> 36511 | D18: 0 | E18: 3000 | F18: RAMESH DIESEL-2000,AUTO-1000, | G18: =C18+D18-E18 -> 33511
A19: 45887 | B19: NIL | C19: =G18 -> 33511 | D19: 0 | E19: 8500 | F19: SANTOSH DIESEL-2000,LADIES SALERY-6000,STAFF SNACKS-500, | G19: =C19+D19-E19 -> 25011
A20: 45888 | B20: NIL | C20: =G19 -> 25011 | D20: 0 | E20: 9700 | F20: SANTOSH DIESEL-3000,RAMESH DIESEL-3000,WELDER-3000,WATER PUMP+CONNECTER-400,PANKAJ PETROL-300 | G20: =C20+D20-E20 -> 15311
A21: 45889 | B21: RAMESH | C21: =G20 -> 15311 | D21: 10130 | E21: 0 | F21: NIL | G21: =C21+D21-E21 -> 25441
A22: 45890 | B22: RAMESH | C22: =G21 -> 25441 | D22: 6170 | E22: 0 | F22: NIL | G22: =C22+D22-E22 -> 31611
A23: 45891 | B23: NIL | C23: =G22 -> 31611 | D23: 0 | E23: 6090 | F23: RAMESH DESEL -3000, SANTHOSH DIESEL - 3000,MILK- 90 | G23: =C23+D23-E23 -> 25521
A24: 45892 | B24: NIL | C24: =G23 -> 25521 | D24: 0 | E24: 3020 | F24: DIESEL-500,STAFF SNACKS-600,SUGAR-50,HOTEL ROOM-1200,ENGINEER LUNCH&BRAEKFAST-380,CAB-291 | G24: =C24+D24-E24 -> 22501
A25: 45893 | B25: SUNDAY | C25: =G24 -> 22501 | D25: 0 | E25: 0 | F25: NIL | G25: =C25+D25-E25 -> 22501
A26: 45894 | B26: NIL | C26: =G25 -> 22501 | D26: 0 | E26: 11900 | F26: EICHER DIESEL-6000(4000PP),KALASHI LUNCH&DINNER-1400,DRIVER BETA-200,POLICE-100,Extra kalashi-4200 | G26: =C26+D26-E26 -> 10601
A27: 45895 | B27: NIL | C27: =G26 -> 10601 | D27: 6000 | E27: 6000 | F27: SANTOSH DIESEL-3000,RAMESH SDIESEL-3000 | G27: =C27+D27-E27 -> 10601
... A32: 45900 | B32: SUNDAY | C32: =G31 -> 12191 | D32: 0 | E32: 0 | F32: SUNDAY | G32: =C32+D32-E32 -> 12191

Sheet Sep-25
A1: Date | B1: SO | C1: Opening Balance | D1: Received Cash | E1: Expenses | F1: Item Details | G1: Balance Amount
A2: 45901 | B2: RAMESH | C2: ='Aug-25'!G32 -> 12191 | D2: 4060 | E2: 4600 | F2: SANTOSH DIESEL-3000,MILK,SUGAR-250,SHAMBHU HYD EXPENSES-1350 | G2: =C2+D2-E2 -> 11651
A3: 45902 | B3: RAMESH | C3: =G2 -> 11651 | D3: 4590 | E3: 1090 | F3: MILK-180,PH METER BATTARY-280,SHULTER GREEZ-130,GANESH CHANDHA-500 | G3: =C3+D3-E3 -> 15151
A4: 45903 | B4: NIL | C4: =G3 -> 15151 | D4: 0 | E4: 6480 | F4: CLUSTER BOND PAPER.12 PIECE-1200,STAFF VEGETABLES,PETROL-700,SANTOSH DIESEL-3000,FAST TAG-500,GROSARIES-1080, | G4: =C4+D4-E4 -> 8671
A5: 45904 | B5: NIL | C5: =G4 -> 8671 | D5: 0 | E5: 3000 | F5: RAMESH DIESEL-3000 | G5: =C5+D5-E5 -> 5671
A6: 45905 | B6: RAMESH | C6: =G5 -> 5671 | D6: 16720 | E6: 9320 | F6: SANTOSH DIESEL-3000,MILK,SUGAR-190,WELDING-50,EICHER DIESEL-5000,KALASHI DINNER-880,DRIVER BETA-200 | G6: =C6+D6-E6 -> 13071
A7: 45906 | B7: RAMESH | C7: =G6 -> 13071 | D7: 6420 | E7: 690 | F7: ANTI SCALE-600,MILK-90, | G7: =C7+D7-E7 -> 18801
A8: 45907 | B8: SUNDAY | C8: =G7 -> 18801 | D8: 0 | E8: 600 | F8: 3BHK STAFF LUNCH AND DINNER-600 | G8: =C8+D8-E8 -> 18201
A9: 45908 | B9: NIL | C9: =G8 -> 18201 | D9: 0 | E9: 2450 | F9: PLANT GAS CILINDER-600,ROOM CILINDER-900,SATFF LUNCH-450,VEGETABLES-500 | G9: =C9+D9-E9 -> 15751
A10: 45909 | B10: NIL | C10: =G9 -> 15751 | D10: 0 | E10: 9770 | F10: RAMESH DIESEL-3000,TOLLGATE-90,EICHER DIESEL-5500,TEA,SNACKS-250,DRIVER BETA-200,GREEZ-200,POLICE-100,MILK-30,STATIONARY-400 | G10: =C10+D10-E10 -> 5981
A11: 45910 | B11: NIL | C11: =G10 -> 5981 | D11: 0 | E11: 90 | F11: MILK-90 | G11: =C11+D11-E11 -> 5891
A12: 45911 | B12: SANTOSH | C12: =G11 -> 5891 | D12: 57250 | E12: 44660 | F12: MILK-180,DRIVER BETA-200,EXTRA HAMALI-800,OVERLOAD FINE-250,TOLL GATE-230,3BHK RENT-7000,LADIES SALARY(6)-36000 | G12: =C12+D12-E12 -> 18481
A13: 45912 | B13: RAMESH | C13: =G12 -> 18481 | D13: 7680 | E13: 6060 | F13: SANTOSH&RAMESH DIESEL-6000,MILK-60, | G13: =C13+D13-E13 -> 20101
A14: 45913 | B14: SANTOSH | C14: =G13 -> 20101 | D14: 4740 | E14: 16790 | F14: SUGAR,MILK-320,EICHER DIESEL-7000,SNACKS-250,RTA-200,DRIVER BETA-200,FASTTAG-2000,3BHK STAFF GROSERIES-6,820 | G14: =C14+D14-E14 -> 8051
... A31: 45930 | B31: NIL | C31: =G30 -> -588 | D31: 0 | E31: 0 | F31: NIL | G31: =C31+D31-E31 -> -588

Sheet Oct-25
A1: Date | B1: SO | C1: Opening Balance | D1: Received Cash | E1: Expenses | F1: Item Details | G1: Balance Amount
A2: 45931 | B2: TULASI RAM | C2: ='Sep-25'!G31 -> -588 | D2: 14980 | E2: 12899 | F2: SANTOSH DIESEL-2500(PP),RAMESH DIESEL-3000,GLOWES-440,STAFF DAUGHTER WEDDING GIFT-5000,MILK(23/9-01/10)-980,SUGAR-165,A4 BUNDLE-260,WIRE-550 | G2: =C2+D2-E2 -> 1493
A3: 45932 | B3: HOLIDAY | C3: =G2 -> 1493 | D3: 0 | E3: 0 | F3: NIL | G3: =C3+D3-E3 -> 1493
A4: 45933 | B4: HOLIDAY | C4: =G3 -> 1493 | D4: 0 | E4: 0 | F4: NIL | G4: =C4+D4-E4 -> 1493
A5: 45934 | B5: SANTOSH | C5: =G4 -> 1493 | D5: 21210 | E5: 13020 | F5: EICHER WATER WASH-600,DRIVER BETA-200,EICHER DIESEL-6000,DEFF OIL-1300,DRIVER BETA-200,MATTON SUPPILER ITEMS-850,2L LABLE COURIER-800,SANTOSH DIESEL-2000,MATTON CUTTER LUNCH-570,MOUUTON CUTTERS TIP-500, | G5: =C5+D5-E5 -> 9683
A6: 45935 | B6: SUNDAY | C6: =G5 -> 9683 | D6: 0 | E6: 0 | F6: NIL | G6: =C6+D6-E6 -> 9683
A7: 45936 | B7: SANTOSH | C7: =G6 -> 9683 | D7: 4440 | E7: 8080 | F7: MILK-200,SANTOSH DIESEL-3000,TOLLGATE-300,RAMESH DIESEL-3000,PANLAJ BIKE REPAIR-550,RAMESH VEHICLE FINE-1030 | G7: =C7+D7-E7 -> 6043
A8: 45937 | B8: RAMESH | C8: =G7 -> 6043 | D8: 1200 | E8: 410 | F8: MEALS FOR STAFF-260,MILK-150 | G8: =C8+D8-E8 -> 6833
A9: 45938 | B9: RAMESH | C9: =G8 -> 6833 | D9: 9730 | E9: 12300 | F9: SANTOSH DIESEL-3000,RAMESH DIESEL-3000,EICHER BODY IRON RODS WELDING-6100,MILK-200, | G9: =C9+D9-E9 -> 4263
A10: 45939 | B10: RAMESH | C10: =G9 -> 4263 | D10: 6900 | E10: 3720 | F10: SRIKAKULAM TOLLGARE-300,PATRUDU DIESEL-3000,MILK-420 | G10: =C10+D10-E10 -> 7443
A11: 45940 | B11: RAMESH | C11: =G10 -> 7443 | D11: 8590 | E11: 14911 | F11: SANTOSH DIESEL-3000,TOLLGATE-200,EICHER DIESEL-8000,FAST TAG-2000,WIFI RECHARGE-1060,RUBBER STAMS(2)-500,AATA-150 | G11: =C11+D11-E11 -> 1122
A12: 45941 | B12: RAMESH | C12: =G11 -> 1122 | D12: 7220 | E12: 6380 | F12: PATRUDU DIESEL-2500,TOLL GATE-200,SANTOSH TILLGATE-300,RAMESH DIESEL-3000,BETA-200,MILK-180 | G12: =C12+D12-E12 -> 1962
A13: 45942 | B13: SUNDAY | C13: =G12 -> 1962 | D13: 0 | E13: 0 | F13: NIL | G13: =C13+D13-E13 -> 1962
A14: 45943 | B14: SANTOSH | C14: =G13 -> 1962 | D14: 3420 | E14: 4630 | F14: MILK-180,SUGAR(5KG)-300,SANTOSH DIESEL-3000,TOLL GATE-300,ANTISCALE-850 | G14: =C14+D14-E14 -> 752
... A26: 45955 | B26: NIL | C26: =G25 -> 8844 | D26: 0 | E26: 0 | F26: NIL | G26: =C26+D26-E26 -> 8844
A27: 45956 | B27: SUNDAY | C27: =G26 -> 8844 | D27: 0 | E27: 0 | F27: 0 | G27: =C27+D27-E27 -> 8844
A28: 45957 | B28: RAMESH/SANTOSH | C28: =G27 -> 8844 | D28: 8570 | E28: 7150 | F28: MILK-360,SANTOSH DIESEL-3000,SHRINK ROLL PARCEL-520,PATRUDU DIESEL-2500,TOLL-300,ARAKU TOLL-80,STAFF MEALS-390 | G28: =C28+D28-E28 -> 10264 | H28: Yanam Vehicle Expenses Return Amount-400/-(added)
A29: 45958 | B29: RAMESH | C29: =G28 -> 10264 | D29: 210 | E29: 3530 | F29: RAMESH DIESEL-3000,MILK/COFEE POWDER-230,POLICE MAMOLU-300 | G29: =C29+D29-E29 -> 6944
A30: 45959 | B30: NIL | C30: =G29 -> 6944 | D30: 0 | E30: 3360 | F30: LAXMAN DIESEL-2820,TOLL-200,MILK-240,STAFF CURRY-100 | G30: =C30+D30-E30 -> 3584
A31: 45960 | B31: RAMESH/SANTOSH | C31: =G30 -> 3584 | D31: 11940 | E31: 490 | F31: MILK-240,STAFF MEALS-250, | G31: =C31+D31-E31 -> 15034
A32: 45961 | B32: RAMESH/SANTOSH | C32: =G31 -> 15034 | D32: 10690 | E32: 18180 | F32: HARI DIESEL,BETA,EXPENSES-7000,MILK/SUGAR-300PATRUDU DIESEL-2000,CHILLER CONTECTER(2)-2340,EICHER ROAD TAX-5040,ANTISCALE(2)-1200,RAPIDO-300 | G32: =C32+D32-E32 -> 7544

Sheet Nov-25
A1: Date | B1: SO | C1: Opening Balance | D1: Received Cash | E1: Expenses | F1: Item Details | G1: Balance Amount | H1: Sent To Tulasi | I1: Remarks
A2: 45962 | B2: RAMESH | C2: ='Oct-25'!G32 -> 7544 | D2: 7840 | E2: 3570 | F2: RAMESH DIESEL-3000,MILK SUGAR-300,ELE RAMESH LUNCH-150,STAFF SNACKS-120 | G2: =C2+D2-E2 -> 11814 | H2: NIL | I2: NIL
A3: 45963 | B3: SUNDAY | C3: =G2 -> 11814 | D3: 0 | E3: 0 | F3: NIL | G3: =C3+D3-E3 -> 11814 | H3: NIL | I3: NIL
A4: 45964 | B4: PATRUDU/LAXMAN | C4: =G3 -> 11814 | D4: 12470 | E4: 4000 | F4: MILK SUGAR-300,SANTOSH DIESEL-3000,MADUGULA UNLOADING SUNDAY-700 | G4: =C4+D4-E4 -> 20284 | H4: NIL | I4: NIL
A5: 45965 | B5: SANTOSH/LAXMAN | C5: =G4 -> 20284 | D5: 8560 | E5: 3510 | F5: MILK SUGAR-300,LAXMAN DIESEL-3000,STAFF LUNCH-210 | G5: =C5+D5-E5 -> 25334 | H5: NIL | I5: NIL
A6: 45966 | B6: SANTOSH/LAXMAN | C6: =G5 -> 25334 | D6: 11850 | E6: 3000 | F6: RAMESH DIESEL-3000, | G6: =C6+D6-E6 -> 34184 | H6: NIL | I6: NIL
A7: 45967 | B7: SANTOSH/LAXMAN | C7: =G6 -> 34184 | D7: 10100 | E7: 2170 | F7: Deeoak dinner- 330, SNK Grand Adv- 1000, staff dinner- 240, Deepak cab- 600, | G7: =C7+D7-E7 -> 42114 | H7: NIL | I7: NIL
A8: 45968 | B8: SANTOSH/LAXMAN | C8: =G7 -> 42114 | D8: 9160 | E8: 1970 | F8: Deepak Tiffen- 90, emiry paper- 200, Deepak lunch -530, Staff Lunch-160, Milk-240, Deepak and staff dinner-750 | G8: =C8+D8-E8 -> 49304 | H8: NIL | I8: NIL
A9: 45969 | B9: SANTHOSH | C9: =G8 -> 49304 | D9: 4050 | E9: 17910 | F9: Eicher fong lamp, horn-5480, Deepak tiffen- 100, lunch-430, santhosh diesel-3000, patrudu diesel-3080, welding-600, pet blowing milling- 3500, pet blowing paking iron pieses-1000, Deepak dinner-480, milk-240 | G9: =C9+D9-E9 -> 35444 | H9: NIL | I9: NIL
A10: 45970 | B10: NIL | C10: =G9 -> 35444 | D10: 0 | E10: 1870 | F10: Deepak Tiffen- 100, sugar, milk-360, Deepak lunch -400,deepak dinner-410, welding -600 | G10: =C10+D10-E10 -> 33574 | H10: NIL | I10: NIL
A11: 45971 | B11: LAXAMAN | C11: =G10 -> 33574 | D11: 11620 | E11: 17740 | F11: Deepak tiffen- 160, laxman diesel-3000, laxman toll gate and RTA Fine-600, deepak lunch-500, Bobbili toll gate-300, patrudu (Rajamandri) diesel, toll gate and Expenses-6420, Ramesh diesel-3000, santhosh toll gate and diesel-3300,Deepak dinner-460, | G11: =C11+D11-E11 -> 27454 | H11: NIL | I11: NIL
A12: 45972 | B12: RAMESH | C12: =G11 -> 27454 | D12: 7660 | E12: 10110 | F12: Deeopak tiffen-100,deepak and sambu lunch-350, Lable retur DTDC and auto -5900,deepak airport droping-360, fevi quick-200, laxman diesel and toll gate- 3200, | G12: =C12+D12-E12 -> 25004 | H12: NIL | I12: NIL
A13: 45973 | B13: SANTHOSH/RAMESH | C13: =G12 -> 25004 | D13: 12370 | E13: 11340 | F13: Eicher kakinada2 and amalapuram diesel and greese, beta, meals-9000, fastrack-1000, pankaj, sambu lunch-240, staff snacks-800, pankaj, sambu dinner-300, | G13: =C13+D13-E13 -> 26034 | H13: NIL | I13: NIL
A14: 45974 | B14: SANTHOSH | C14: =G13 -> 26034 | D14: 5970 | E14: 19077 | F14: flate kirana, veztables- 6927, pankaj and shambu lunch-250, flate rent-7000, snk grand(deepak)-4000, staff snaks-900, | G14: =C14+D14-E14 -> 12927 | H14: NIL | I14: NIL
... A22: 45983 | B22: SANTHOSH/RAMESH/ PATRUDU | C22: =G21 -> 28521 | D22: 52680 | E22: 52610 | F22: 3BHK Vegtables-600, VR Indistries-20,000, staff snaks-800, sugar 2kgs-130, milk17.11.25 to 22.11.25-1080, | G22: =C22+D22-E22 -> 28591 | H22: NIL | I22: Actul Payment to VR Idustries 50,000/-(30,000/- santhosh sir payed, 20,000/- secondary sale payed)
A23: 45984 | B23: sunday | C23: =G22 -> 28591 | D23: 0 | E23: 0 | F23: NIL | G23: =C23+D23-E23 -> 28591
A24: 45985 | B24: SANTHOSH/RAMESH | C24: =G23 -> 28591 | D24: 20110 | E24: 7300 | F24: santhosh deisel-3000, ramesh deiisel-3000, ktv locks-500, staff snaks-800, | G24: =C24+D24-E24 -> 41401 | H24: NIL | I24: NIL
A25: 45986 | B25: SANTHOSH/RAMESH | C25: =G24 -> 41401 | D25: 14960 | E25: 8190 | F25: Icher deisel, beta, PC,RTA-7000, Staff snaks-800, sugar 6kgs-390, | G25: =C25+D25-E25 -> 48171 | H25: NIL | I25: NIL
A26: 45987 | B26: SANTHOSH/RAMESH | C26: =G25 -> 48171 | D26: 21730 | E26: 11080 | F26: staff snaks-800, tea pudi-280, suresh SR Adv-10000, | G26: =C26+D26-E26 -> 58821 | H26: NIL | I26: NIL
A27: 45988 | B27: SANTHOSH/RAMESH | C27: =G26 -> 58821 | D27: 16380 | E27: 25950 | F27: Icher deisel, beta, expenses, labour, def oil-10000, fast trak-2000, laxman deisel-3000, tollgate, expenses-350, patrudu deisel-3000, santhosh deisel-3000, ramesh deisel-3000, pankaj petrol-600, staff snaks-800, cello tap-200, | G27: =C27+D27-E27 -> 49251 | H27: NIL | I27: NIL
A28: 45989 | B28: SANTHOSH/RAMESH | C28: =G27 -> 49251 | D28: 13680 | E28: 1700 | F28: staff snaks-700, yadav adv-1000, | G28: =C28+D28-E28 -> 61231 | H28: NIL | I28: NIL
A29: 45990 | B29: SANTHOSH/RAMESH | C29: =G28 -> 61231 | D29: 40830 | E29: 96630 | F29: paid to inmoisture account-50000, staff snaks-700, 3bhk veztables-650,sambu adv-5000, millk(24.11.2025 to 29.11.2025)6days-1080, ladies salary-36000, patrudu deisel, tollgate-3200, | G29: =C29+D29-E29 -> 5431 | H29: NIL | I29: Santhosh amount-5730, ramesh amount -8230,simba fuction hall payment-15600+scrap amount-8830+shrink scrap amount-2440. Total Amount= 40,830/-
A30: 45991 | B30: SUNDAY | C30: =G29 -> 5431 | D30: 0 | E30: 0 | F30: NIL | G30: =C30+D30-E30 -> 5431 | H30: NIL

Sheet Dec-25
A1: Date | B1: SO | C1: Opening Balance | D1: Received Cash | E1: Expenses | F1: Item Details | G1: Balance Amount | H1: Sent To Tulasi | I1: Remarks
A2: 45992 | B2: SANTHOSH/ RAMESH | C2: ='Nov-25'!G30 -> 5431 | D2: 14150 | E2: 10600 | F2: santhosh deisel-3000, ramesh deisel-3000, grees-200, laxman deisel, tollgate, expenses-3400, staff snaks-700, 3bhk atta-300. | G2: =C2+D2-E2 -> 8981 | H2: NIL | I2: NIL
A3: 45993 | B3: SANTHOSH/ RAMESH | C3: =G2 -> 8981 | D3: 19290 | E3: 850 | F3: staff snaks-650, ozon pump paipe-200, | G3: =C3+D3-E3 -> 27421 | H3: NIL | I3: NIL
A4: 45994 | B4: SANTHOSH/ RAMESH | C4: =G3 -> 27421 | D4: 8630 | E4: 1300 | F4: STAFF SNAKS-750, TEA And Coffee powder-550, | G4: =C4+D4-E4 -> 34751 | H4: NIL | I4: NIL
A5: 45995 | B5: SANTHOSH/ RAMESH | C5: =G4 -> 34751 | D5: 8900 | E5: 4400 | F5: ramesh deisel-3000, tank cleaning brushs-430, MCB-270, staff snaks-700 | G5: =C5+D5-E5 -> 39251 | H5: NIL | I5: Santhosh amount-3250, Ramesh amount- 3010,gajuwaka 250ml-22 cases -2640 c/o. karuna garu.amount added daily expenses. Total amount-8900.
A6: 45996 | B6: SANTHOSH/ RAMESH | C6: =G5 -> 39251 | D6: 11970 | E6: 10955 | F6: patrudu deisel, tollgate, meels-5200, santhosh deisel-3000, chlorin-800, lable parsel delhi-955, staff snaks-700, 3bhk refund oil-300, | G6: =C6+D6-E6 -> 40266 | H6: NIL | I6: NIL
A7: 45997 | B7: SANTHOSH/ RAMESH | C7: =G6 -> 40266 | D7: 10610 | E7: 21080 | F7: gas-3bhk/plant-1800, staff snaks-800, milk(01-12-25 to 06-12-25)-1080, grees-400, hari deisel-9500, fastrack-500, 3bhk rent- 7000, | G7: =C7+D7-E7 -> 29796 | H7: NIL | I7: NIL
A8: 45998 | B8: SUNDAY | C8: =G7 -> 29796 | D8: 0 | E8: 0 | G8: =C8+D8-E8 -> 29796 | H8: NIL | I8: SUNDAY
A9: 45999 | B9: SANTHOSH/ RAMESH | C9: =G8 -> 29796 | D9: 14050 | E9: 11250 | F9: 3bhk vegtables, atta-900, staff snaks-700, brooms-450, patrudu deisel-3000, santhosh deisel-3000, ramesh deisel-3000, cello taps-200, | G9: =C9+D9-E9 -> 32596 | H9: NIL | I9: NIL
A10: 46000 | B10: SANTHOSH/ RAMESH | C10: =G9 -> 32596 | D10: 13670 | E10: 6150 | F10: staff snaks-700, hari deisel,beta,expenses-5450, | G10: =C10+D10-E10 -> 40116 | H10: NIL | I10: NIL
A11: 46001 | B11: SANTHOSH/ RAMESH | C11: =G10 -> 40116 | D11: 11100 | E11: 14331 | F11: allen bolts,allenkys-740, concters,paipes-2124, tap set,tap handle-2217, sambu lunch-250, hari deisel,beta,pc,expenses-7200, masks-600, pankaj petrol-500, staff snaks-700, | G11: =C11+D11-E11 -> 36885 | H11: NIL | I11: NIL
A12: 46002 | B12: SANTHOSH/ RAMESH | C12: =G11 -> 36885 | D12: 10050 | E12: 23800 | F12: santhosh deisel-3000, laxman deise,tollgate-3300, patrudu deisel,tollgate-3300, staff snaks-700, ramesh deisel-3000, hari deisel,beta,grees,pc,expenses-8000, fastrack-2000, pet blowing welding(06.12.25)-500 | G12: =C12+D12-E12 -> 23135 | H12: NIL | I12: NIL
A13: 46003 | B13: SANTHOSH/ RAMESH | C13: =G12 -> 23135 | D13: 10560 | E13: 5730 | F13: naveen,yaswanth lunch-200, chinna deisel-1000, staff snaks-700, sambu hyd expences-3000, naveen petrol(ankith)-300, ankith dinner-530, | G13: =C13+D13-E13 -> 27965 | H13: NIL | I13: NIL
A14: 46004 | B14: SANTHOSH/ RAMESH | C14: =G13 -> 27965 | D14: 21760 | E14: 3950 | F14: pet blowing bearings-2 -1900, ankith tiffen-160, krishna petrol-100, ankith lunch-400, 3bhk oil 2 pakets-310, milk(08.12.25 to 13.12.25)-1080 | G14: =C14+D14-E14 -> 45775 | H14: NIL | I14: NIL
A15: 46005 | B15: SUNDAY | C15: =G14 -> 45775 | D15: 0 | E15: 2950 | F15: 13.12.2025 ankith dinner-200, ankith tiffen-150, ankith, staff lunch-1600, lethi measion charges-800, ankith dinner-200, | G15: =C15+D15-E15 -> 42825 | H15: NIL | I15: SUNDAY
A16: 46006 | B16: SANTHOSH/ RAMESH | C16: =G15 -> 42825 | D16: 18840 | E16: 1640 | F16: ankith tiffen-110, coffe, tea powder-470, Ankith,staff lunch-450, ankith dinner-430, pass port size photos(owner mother)-180 | G16: =C16+D16-E16 -> 60025 | H16: NIL | I16: NIL
A17: 46007 | B17: SANTHOSH/ RAMESH/ LAXMAN/ CHINNA | C17: =G16 -> 60025 | D17: 17460 | E17: 14600 | F17: ramesh deisel-3000, 3bhk veztables-600, ankith tiffen-110, krishna petrol-100, chemical for grass-1250, santhosh deisel-3000, laxman deisel-3000, chinna deisel-3000, ankith lunch-280, ankith dinner-260, | G17: =C17+D17-E17 -> 62885 | H17: NIL | I17: NIL
A18: 46008 | B18: SANTHOSH/ RAMESH/ LAXMAN/ CHINNA | C18: =G17 -> 62885 | D18: 16430 | E18: 22421 | F18: BIS Expenses-10000, ankith extra lauggeg-2800, (dhelli company to airport-761, food-250, SNK Grand to airport-300, dhelli airport to house, food-2000, staff snaks-700, 3bhk atta,oil-610, SNK Grand room bill-5000, | G18: =C18+D18-E18 -> 56894 | H18: NIL | I18: NIL
A19: 46009 | B19: SANTHOSH/ RAMESH/ LAXMAN/ CHINNA | C19: =G18 -> 56894 | D19: 14580 | E19: 16850 | F19: patrudu deisel-3000, staff snaks-350, yadav 20days salary-13500, | G19: =C19+D19-E19 -> 54624 | H19: NIL | I19: NIL
A20: 46010 | B20: SANTHOSH/ LAXMAN/ CHINNA | C20: =G19 -> 54624 | D20: 8290 | E20: 19032 | F20: Hari akp expenses-500, staff snaks-700, sugar 2kgs-100, chinna deisel-3000, staff dinner-1232, shambu hyd-500, V Chemicals-13000, | G20: =C20+D20-E20 -> 43882 | H20: NIL | I20: NIL
... A28: 46018 | B28: SANTHOSH/ RAMESH/ CHINNA/ PATHRUDU | C28: =G27 -> 52977 | D28: 17680 | E28: 42000 | F28: mohan hosptal-800, ramesh deisel-3000, hari(anakapalli expenses)-1000, pankaj petrol-500, staff snaks-700, ladies salarys-36000. | G28: =C28+D28-E28 -> 28657 | H28: NIL | I28: secondry sale :- santhosh-5480, ramesh-7130, pathrudu-2740, chinna-730, Plant sale-1100, ktv sale-500(sudha 6cases 1ltr) Total-17680
A29: 46019 | B29: sunday | C29: =G28 -> 28657 | D29: 0 | E29: 0 | G29: =C29+D29-E29 -> 28657 | H29: NIL | I29: NIL
A30: 46020 | B30: SANTHOSH/ RAMESH/ CHINNA/ PATHRUDU | C30: =G29 -> 28657 | D30: 17850 | E30: 15050 | F30: 3bvhk vegetables-500, milk (21-12-2025-27-12-2025)- 1260, staff snaks-700, l anki squrus, nut and bolds-850, coffe poweder-490, hari deisel, beta, pc, expenses, unloading(rajam)-10000, fastrack-1000, sugar 5kgs-250, | G30: =C30+D30-E30 -> 31457 | H30: NIL | I30: NIL
A31: 46021 | B31: SANTHOSH/ RAMESH/ PATHRUDU | C31: =G30 -> 31457 | D31: 19120 | E31: 6800 | F31: laxman deisel-3000, chinna deisel-3000, snaks-800 | G31: =C31+D31-E31 -> 43777 | H31: NIL | I31: NIL
A32: 46022 | B32: SANTHOSH/ RAMESH/ CHINNA/ PATHRUDU | C32: =G31 -> 43777 | D32: 19140 | E32: 17700 | F32: santhosh deisel-3000, plant deisel-500, pathrudu deisel-3000, staff snaks-700, tea powder 1kg-600, hari deisel,beta,meeals,rta,greesing,(bobbili ,makkuva)unloading-9900, | G32: =C32+D32-E32 -> 45217 | H32: NIL | I32: NIL

Sheet Jan-26
A1: Date | B1: SO | C1: Opening Balance | D1: Received Cash | E1: Expenses | F1: Item Details | G1: Balance Amount | H1: Remarks
A2: 46023 | B2: SANTHOSH/ RAMESH/ PATHRUDU | C2: ='Dec-25'!G32 -> 45217 | D2: 12090 | E2: 6240 | F2: concters-650, ramesh deisel-3000, staff snaks-800, ktv bulb-180, tap-160, ozone circute DTDCA-250, welding-500, lap top bag-700, | G2: =C2+D2-E2 -> 51067 | H2: NIL
A3: 46024 | B3: SANTHOSH/ RAMESH/ LAXMAN/ PATHRUDU | C3: =G2 -> 51067 | D3: 13050 | E3: 10700 | F3: staff snaks-700, hari- parvathipuram-10000, | G3: =C3+D3-E3 -> 53417 | H3: NIL
A4: 46025 | B4: SANTHOSH/ RAMESH/ LAXMAN/ PATHRUDU | C4: =G3 -> 53417 | D4: 21370 | E4: 21770 | F4: laxman deisel-3000, santhosh deisel-3000, milk 29-12-2026 to 03-01-2026 - 1080, G.Yenky naidu(kalasi) salary-13990, staff snaks-700, | G4: =C4+D4-E4 -> 53017 | H4: NIL
A5: 46026 | B5: SUNDAY | C5: =G4 -> 53017 | D5: 0 | E5: 0 | F5: NILL | G5: =C5+D5-E5 -> 53017 | H5: NIL
A6: 46027 | B6: SANTHOSH/ RAMESH/ LAXMAN/ CHINNA | C6: =G5 -> 53017 | D6: 16630 | E6: 27240 | F6: 3bhk veztables,rice-1000, hari deisel madugula,beta,expenses(kalasi, driver meeals)-4800, staff snaks-700, 12 size paipe 10 miters-750, pampu oil seeal-2250, sumit elctricals-3140, ramesh deisel-3000, chinna deisel-3000, office tables-2 - 8600, | G6: =C6+D6-E6 -> 42407 | H6: NIL
A7: 46028 | B7: SANTHOSH/ RAMESH/ LAXMAN/ CHINNA | C7: =G6 -> 42407 | D7: 16120 | E7: 13050 | F7: MCB Rapido-250, staff snaks-800, hari deisel kakinada,beta,unloading,pc, other expenses,10000, fastrak-2000 | G7: =C7+D7-E7 -> 45477 | H7: NIL
A8: 46029 | B8: SANTHOSH/ RAMESH/ LAXMAN/ CHINNA | C8: =G7 -> 45477 | D8: 11840 | E8: 18700 | F8: Hari deisel bobbili, unloading,beta,wate wash,expenses-9000, pathrudu diesel-3000, laxman diesel-3000, santhosh diesel-3000, snaks-700 | G8: =C8+D8-E8 -> 38617 | H8: NIL
A9: 46030 | B9: SANTHOSH/ RAMESH/ LAXMAN/ CHINNA | C9: =G8 -> 38617 | D9: 10345 | E9: 41435 | F9: hari diesel srikakulam and rajam,beta,unloading,meeals, pc-9700, fastrack-1000, air dryer repair sper parts -7785, anti sclae and filters transfort-1060, SR Ravi 5days TA DA-900, 3BHK rent-7000, K.Suribabu kalasi salary-13990, | G9: =C9+D9-E9 -> 7527 | H9: NIL
